Workbook

Sheet SETUP
A1: RENEWAL MANAGEMENT TOOL — PROPERTY SETUP
A2: PROPERTY CONFIGURATION
A3: Property Name: | B3: RISE Citrus Ridge | C3: ← Enter your property name here (blue = input cell)
A4: Month / Year: | B4: March 2026 | C4: ← Enter month and year (e.g., 'April 2026')
A6: FLOOR PLAN CONFIGURATION — Rates & Occupancy by Unit Type
A7: Enter each floor plan type, its current market rate, budget rate, and occupancy status. The renewal tracker sheet uses these values to auto-populate offers — just enter the Unit Type and everything calculates.
A8: Floor Plan Type | B8: Market Rate ($) | C8: Budget Rate ($) | D8: Occupancy Status (Under / Over) | E8: Unit Description / Notes
A9: B1 | B9: 2150 | C9: 2181 | D9: Under | E9: 1 Bed / 1 Bath
A10: C1 | B10: 2295 | C10: 2626 | D10: Under | E10: 2 Bed / 2 Bath
A19: ⚠ Occupancy Status: Type "Under" when floor plan is below occupancy budget target, "Over" when above it. This controls which offer formula tier is applied.
A21: HOW TO USE THIS TOOL
A22: Step 1 — Configure: | B22: Update Property Name and Month/Year above. Enter all floor plan types with market rates, budget rates, and occupancy status (Under/Over). These feed every renewal sheet automatically.
A23: Step 2 — Enter Residents: | B23: Go to the monthly renewal sheet (e.g., 'Mar 2026'). Type resident data in the orange columns: Name, Unit, Unit Type, Expiration Date, Deposit Held, and Current Rate. All other columns calculate automatically.
A24: Step 3 — Track Decisions: | B24: As decisions come in, enter dates or notes in the Renewal Signed, Transfer, or NTV Rcv'd columns. Rows auto-color: Green = Renewed, Red = NTV, Blue = Transfer, Yellow = Pending.
A25: Step 4 — New Month: | B25: Right-click the TEMPLATE tab → 'Move or Copy' → check 'Create a copy' → rename to new month (e.g., 'Apr 2026'). Update Month/Year in this SETUP sheet.
A26: Step 5 — New Property: | B26: Save a copy of this entire workbook with the new property name. Then update SETUP with the new property name and its floor plan configuration. All sheets reference SETUP automatically.
A28: ROW COLOR CODING (auto-applied based on status entries)
A29: Renewed | B29: A date/value entered in 'Renewal Signed' column (N) turns the row green
A30: NTV (Notice to Vacate) | B30: A date/value entered in 'NTV Rcv'd' column (P) turns the row red
A31: Transfer | B31: A date/value entered in 'Transfer' column (O) turns the row blue
A32: Pending Signature | B32: Color manually with yellow fill using Excel's fill tool
A33: MTM (Month-to-Month) | B33: Color manually with gray fill using Excel's fill tool

Sheet Mar 2026
A1: =SETUP!B3&" - "&SETUP!B4&" Renewals"
A2: Name | B2: Unit | C2: Unit Type | D2: Expiration Date | E2: 90-Day Notice | F2: 60-Day Notice | G2: 30-Day Notice | H2: Deposit Held | I2: Current Rate | J2: Recommended Offer | K2: Investor Override % Increase | L2: Investor Override Offer | M2: Offer 1 Conservative | N2: Offer 2 Balanced | O2: Offer 3 Aggressive | P2: Signed Offer | Q2: Renewal Signed | R2: Transfer | S2: NTV Rcv'd | T2: Phone | U2: Notes | V2: Market Rate | W2: Budget | X2: Occupancy (Under/Over) | Y2: Rent Growth Offer 1 | Z2: Rent Growth Offer 2 | AA2: Rent Growth Offer 3 | AB2: Signed Rent Growth
A3: ▼ Enter | B3: ▼ Enter | C3: ▼ Enter | D3: ▼ Enter | E3: ◀ Auto | F3: ◀ Auto | G3: ◀ Auto | H3: ▼ Enter | I3: ▼ Enter | J3: ◀ Auto | K3: ▼ Enter | L3: ◀ Auto | M3: ◀ Auto | N3: ◀ Auto | O3: ◀ Auto | P3: ▼ Select | Q3: ▼ Enter | R3: ▼ Enter | S3: ▼ Enter | T3: ▼ Enter | U3: ▼ Enter | V3: ◀ Auto | W3: ◀ Auto | X3: ◀ Auto | Y3: ◀ Auto | Z3: ◀ Auto | AA3: ◀ Auto | AB3: ◀ Auto
A4: Adolfo Trevino III | B4: 3-2055 | C4: C1 | D4: 46173 | E4: =IF(D4="","",D4-90) | F4: =IF(D4="","",D4-60) | G4: =IF(D4="","",D4-30) | H4: 500 | I4: 2195 | J4: =IF(I4="","",IF(ABS(N4-W4)<=ABS(M4-W4),IF(ABS(N4-W4)<=ABS(O4-W4),"Offer 2","Offer 3"),IF(ABS(M4-W4)<=ABS(O4-W4),"Offer 1","Offer 3"))) | L4: =IF(OR(I4="",K4=""),"",CEILING(I4*(1+K4),5)) | M4: =IF(I4="","",IF(X4="Under",CEILING(MAX(I4*1.02,MIN(V4,W4)*0.95),5),CEILING(MAX(I4*1.03,MIN(V4,W4)*0.97),5))) | N4: =IF(I4="","",IF(X4="Under",CEILING(MAX(I4*1.03,(V4+W4)/2*0.96),5),CEILING(MAX(I4*1.05,(V4+W4)/2*0.98),5))) | O4: =IF(I4="","",IF(X4="Under",CEILING(MAX(I4*1.05,MIN(V4,W4*1.01)),5),CEILING(MAX(I4*1.08,MIN(V4,W4*1.02)),5))) | V4: =IF(C4="","",IFERROR(VLOOKUP(C4,SETUP!$A$9:$D$18,2,0),"⚠ Check SETUP")) | W4: =IF(C4="","",IFERROR(VLOOKUP(C4,SETUP!$A$9:$D$18,3,0),"⚠ Check SETUP")) | X4: =IF(C4="","",IFERROR(VLOOKUP(C4,SETUP!$A$9:$D$18,4,0),"⚠ Check SETUP")) | Y4: =IF(OR(I4="",M4=""),"",(M4-I4)/I4) | Z4: =IF(OR(I4="",N4=""),"",(N4-I4)/I4) | AA4: =IF(OR(I4="",O4=""),"",(O4-I4)/I4) | AB4: =IF(OR(Q4="",S4<>"",P4="",I4=""),"",IF(P4="Investor Override",IF(L4="","",(L4-I4)/I4),IF(P4="Offer 1",IF(M4="","",(M4-I4)/I4),IF(P4="Offer 2",IF(N4="","",(N4-I4)/I4),IF(P4="Offer 3",IF(O4="","",(O4-I4)/I4),"")))))
A5: Shania Folkes | B5: 13-2197 | C5: B1 | D5: 46174 | E5: =IF(D5="","",D5-90) | F5: =IF(D5="","",D5-60) | G5: =IF(D5="","",D5-30) | H5: 0 | I5: 1895 | J5: =IF(I5="","",IF(ABS(N5-W5)<=ABS(M5-W5),IF(ABS(N5-W5)<=ABS(O5-W5),"Offer 2","Offer 3"),IF(ABS(M5-W5)<=ABS(O5-W5),"Offer 1","Offer 3"))) | L5: =IF(OR(I5="",K5=""),"",CEILING(I5*(1+K5),5)) | M5: =IF(I5="","",IF(X5="Under",CEILING(MAX(I5*1.02,MIN(V5,W5)*0.95),5),CEILING(MAX(I5*1.03,MIN(V5,W5)*0.97),5))) | N5: =IF(I5="","",IF(X5="Under",CEILING(MAX(I5*1.03,(V5+W5)/2*0.96),5),CEILING(MAX(I5*1.05,(V5+W5)/2*0.98),5))) | O5: =IF(I5="","",IF(X5="Under",CEILING(MAX(I5*1.05,MIN(V5,W5*1.01)),5),CEILING(MAX(I5*1.08,MIN(V5,W5*1.02)),5))) | V5: =IF(C5="","",IFERROR(VLOOKUP(C5,SETUP!$A$9:$D$18,2,0),"⚠ Check SETUP")) | W5: =IF(C5="","",IFERROR(VLOOKUP(C5,SETUP!$A$9:$D$18,3,0),"⚠ Check SETUP")) | X5: =IF(C5="","",IFERROR(VLOOKUP(C5,SETUP!$A$9:$D$18,4,0),"⚠ Check SETUP")) | Y5: =IF(OR(I5="",M5=""),"",(M5-I5)/I5) | Z5: =IF(OR(I5="",N5=""),"",(N5-I5)/I5) | AA5: =IF(OR(I5="",O5=""),"",(O5-I5)/I5) | AB5: =IF(OR(Q5="",S5<>"",P5="",I5=""),"",IF(P5="Investor Override",IF(L5="","",(L5-I5)/I5),IF(P5="Offer 1",IF(M5="","",(M5-I5)/I5),IF(P5="Offer 2",IF(N5="","",(N5-I5)/I5),IF(P5="Offer 3",IF(O5="","",(O5-I5)/I5),"")))))
A6: Monique Mayhue | B6: 11-2153 | C6: C1 | D6: 46177 | E6: =IF(D6="","",D6-90) | F6: =IF(D6="","",D6-60) | G6: =IF(D6="","",D6-30) | H6: 2195 | I6: 2195 | J6: =IF(I6="","",IF(ABS(N6-W6)<=ABS(M6-W6),IF(ABS(N6-W6)<=ABS(O6-W6),"Offer 2","Offer 3"),IF(ABS(M6-W6)<=ABS(O6-W6),"Offer 1","Offer 3"))) | L6: =IF(OR(I6="",K6=""),"",CEILING(I6*(1+K6),5)) | M6: =IF(I6="","",IF(X6="Under",CEILING(MAX(I6*1.02,MIN(V6,W6)*0.95),5),CEILING(MAX(I6*1.03,MIN(V6,W6)*0.97),5))) | N6: =IF(I6="","",IF(X6="Under",CEILING(MAX(I6*1.03,(V6+W6)/2*0.96),5),CEILING(MAX(I6*1.05,(V6+W6)/2*0.98),5))) | O6: =IF(I6="","",IF(X6="Under",CEILING(MAX(I6*1.05,MIN(V6,W6*1.01)),5),CEILING(MAX(I6*1.08,MIN(V6,W6*1.02)),5))) | V6: =IF(C6="","",IFERROR(VLOOKUP(C6,SETUP!$A$9:$D$18,2,0),"⚠ Check SETUP")) | W6: =IF(C6="","",IFERROR(VLOOKUP(C6,SETUP!$A$9:$D$18,3,0),"⚠ Check SETUP")) | X6: =IF(C6="","",IFERROR(VLOOKUP(C6,SETUP!$A$9:$D$18,4,0),"⚠ Check SETUP")) | Y6: =IF(OR(I6="",M6=""),"",(M6-I6)/I6) | Z6: =IF(OR(I6="",N6=""),"",(N6-I6)/I6) | AA6: =IF(OR(I6="",O6=""),"",(O6-I6)/I6) | AB6: =IF(OR(Q6="",S6<>"",P6="",I6=""),"",IF(P6="Investor Override",IF(L6="","",(L6-I6)/I6),IF(P6="Offer 1",IF(M6="","",(M6-I6)/I6),IF(P6="Offer 2",IF(N6="","",(N6-I6)/I6),IF(P6="Offer 3",IF(O6="","",(O6-I6)/I6),"")))))
A7: Samaria Burrell | B7: 11-2157 | C7: B1 | D7: 46180 | E7: =IF(D7="","",D7-90) | F7: =IF(D7="","",D7-60) | G7: =IF(D7="","",D7-30) | H7: 1895 | I7: 1895 | J7: =IF(I7="","",IF(ABS(N7-W7)<=ABS(M7-W7),IF(ABS(N7-W7)<=ABS(O7-W7),"Offer 2","Offer 3"),IF(ABS(M7-W7)<=ABS(O7-W7),"Offer 1","Offer 3"))) | L7: =IF(OR(I7="",K7=""),"",CEILING(I7*(1+K7),5)) | M7: =IF(I7="","",IF(X7="Under",CEILING(MAX(I7*1.02,MIN(V7,W7)*0.95),5),CEILING(MAX(I7*1.03,MIN(V7,W7)*0.97),5))) | N7: =IF(I7="","",IF(X7="Under",CEILING(MAX(I7*1.03,(V7+W7)/2*0.96),5),CEILING(MAX(I7*1.05,(V7+W7)/2*0.98),5))) | O7: =IF(I7="","",IF(X7="Under",CEILING(MAX(I7*1.05,MIN(V7,W7*1.01)),5),CEILING(MAX(I7*1.08,MIN(V7,W7*1.02)),5))) | V7: =IF(C7="","",IFERROR(VLOOKUP(C7,SETUP!$A$9:$D$18,2,0),"⚠ Check SETUP")) | W7: =IF(C7="","",IFERROR(VLOOKUP(C7,SETUP!$A$9:$D$18,3,0),"⚠ Check SETUP")) | X7: =IF(C7="","",IFERROR(VLOOKUP(C7,SETUP!$A$9:$D$18,4,0),"⚠ Check SETUP")) | Y7: =IF(OR(I7="",M7=""),"",(M7-I7)/I7) | Z7: =IF(OR(I7="",N7=""),"",(N7-I7)/I7) | AA7: =IF(OR(I7="",O7=""),"",(O7-I7)/I7) | AB7: =IF(OR(Q7="",S7<>"",P7="",I7=""),"",IF(P7="Investor Override",IF(L7="","",(L7-I7)/I7),IF(P7="Offer 1",IF(M7="","",(M7-I7)/I7),IF(P7="Offer 2",IF(N7="","",(N7-I7)/I7),IF(P7="Offer 3",IF(O7="","",(O7-I7)/I7),"")))))
A8: Maddie Boquet | B8: 12-2191 | C8: B1 | D8: 46195 | E8: =IF(D8="","",D8-90) | F8: =IF(D8="","",D8-60) | G8: =IF(D8="","",D8-30) | H8: 0 | I8: 1895 | J8: =IF(I8="","",IF(ABS(N8-W8)<=ABS(M8-W8),IF(ABS(N8-W8)<=ABS(O8-W8),"Offer 2","Offer 3"),IF(ABS(M8-W8)<=ABS(O8-W8),"Offer 1","Offer 3"))) | L8: =IF(OR(I8="",K8=""),"",CEILING(I8*(1+K8),5)) | M8: =IF(I8="","",IF(X8="Under",CEILING(MAX(I8*1.02,MIN(V8,W8)*0.95),5),CEILING(MAX(I8*1.03,MIN(V8,W8)*0.97),5))) | N8: =IF(I8="","",IF(X8="Under",CEILING(MAX(I8*1.03,(V8+W8)/2*0.96),5),CEILING(MAX(I8*1.05,(V8+W8)/2*0.98),5))) | O8: =IF(I8="","",IF(X8="Under",CEILING(MAX(I8*1.05,MIN(V8,W8*1.01)),5),CEILING(MAX(I8*1.08,MIN(V8,W8*1.02)),5))) | V8: =IF(C8="","",IFERROR(VLOOKUP(C8,SETUP!$A$9:$D$18,2,0),"⚠ Check SETUP")) | W8: =IF(C8="","",IFERROR(VLOOKUP(C8,SETUP!$A$9:$D$18,3,0),"⚠ Check SETUP")) | X8: =IF(C8="","",IFERROR(VLOOKUP(C8,SETUP!$A$9:$D$18,4,0),"⚠ Check SETUP")) | Y8: =IF(OR(I8="",M8=""),"",(M8-I8)/I8) | Z8: =IF(OR(I8="",N8=""),"",(N8-I8)/I8) | AA8: =IF(OR(I8="",O8=""),"",(O8-I8)/I8) | AB8: =IF(OR(Q8="",S8<>"",P8="",I8=""),"",IF(P8="Investor Override",IF(L8="","",(L8-I8)/I8),IF(P8="Offer 1",IF(M8="","",(M8-I8)/I8),IF(P8="Offer 2",IF(N8="","",(N8-I8)/I8),IF(P8="Offer 3",IF(O8="","",(O8-I8)/I8),"")))))
A9: Juan Rodriguez | B9: 7-2134 | C9: C1 | D9: 46198 | E9: =IF(D9="","",D9-90) | F9: =IF(D9="","",D9-60) | G9: =IF(D9="","",D9-30) | H9: 0 | I9: 2195 | J9: =IF(I9="","",IF(ABS(N9-W9)<=ABS(M9-W9),IF(ABS(N9-W9)<=ABS(O9-W9),"Offer 2","Offer 3"),IF(ABS(M9-W9)<=ABS(O9-W9),"Offer 1","Offer 3"))) | L9: =IF(OR(I9="",K9=""),"",CEILING(I9*(1+K9),5)) | M9: =IF(I9="","",IF(X9="Under",CEILING(MAX(I9*1.02,MIN(V9,W9)*0.95),5),CEILING(MAX(I9*1.03,MIN(V9,W9)*0.97),5))) | N9: =IF(I9="","",IF(X9="Under",CEILING(MAX(I9*1.03,(V9+W9)/2*0.96),5),CEILING(MAX(I9*1.05,(V9+W9)/2*0.98),5))) | O9: =IF(I9="","",IF(X9="Under",CEILING(MAX(I9*1.05,MIN(V9,W9*1.01)),5),CEILING(MAX(I9*1.08,MIN(V9,W9*1.02)),5))) | V9: =IF(C9="","",IFERROR(VLOOKUP(C9,SETUP!$A$9:$D$18,2,0),"⚠ Check SETUP")) | W9: =IF(C9="","",IFERROR(VLOOKUP(C9,SETUP!$A$9:$D$18,3,0),"⚠ Check SETUP")) | X9: =IF(C9="","",IFERROR(VLOOKUP(C9,SETUP!$A$9:$D$18,4,0),"⚠ Check SETUP")) | Y9: =IF(OR(I9="",M9=""),"",(M9-I9)/I9) | Z9: =IF(OR(I9="",N9=""),"",(N9-I9)/I9) | AA9: =IF(OR(I9="",O9=""),"",(O9-I9)/I9) | AB9: =IF(OR(Q9="",S9<>"",P9="",I9=""),"",IF(P9="Investor Override",IF(L9="","",(L9-I9)/I9),IF(P9="Offer 1",IF(M9="","",(M9-I9)/I9),IF(P9="Offer 2",IF(N9="","",(N9-I9)/I9),IF(P9="Offer 3",IF(O9="","",(O9-I9)/I9),"")))))
A10: Elizabeth Cook | B10: 8-2156 | C10: C1 | D10: 46203 | E10: =IF(D10="","",D10-90) | F10: =IF(D10="","",D10-60) | G10: =IF(D10="","",D10-30) | H10: 0 | I10: 2195 | J10: =IF(I10="","",IF(ABS(N10-W10)<=ABS(M10-W10),IF(ABS(N10-W10)<=ABS(O10-W10),"Offer 2","Offer 3"),IF(ABS(M10-W10)<=ABS(O10-W10),"Offer 1","Offer 3"))) | L10: =IF(OR(I10="",K10=""),"",CEILING(I10*(1+K10),5)) | M10: =IF(I10="","",IF(X10="Under",CEILING(MAX(I10*1.02,MIN(V10,W10)*0.95),5),CEILING(MAX(I10*1.03,MIN(V10,W10)*0.97),5))) | N10: =IF(I10="","",IF(X10="Under",CEILING(MAX(I10*1.03,(V10+W10)/2*0.96),5),CEILING(MAX(I10*1.05,(V10+W10)/2*0.98),5))) | O10: =IF(I10="","",IF(X10="Under",CEILING(MAX(I10*1.05,MIN(V10,W10*1.01)),5),CEILING(MAX(I10*1.08,MIN(V10,W10*1.02)),5))) | V10: =IF(C10="","",IFERROR(VLOOKUP(C10,SETUP!$A$9:$D$18,2,0),"⚠ Check SETUP")) | W10: =IF(C10="","",IFERROR(VLOOKUP(C10,SETUP!$A$9:$D$18,3,0),"⚠ Check SETUP")) | X10: =IF(C10="","",IFERROR(VLOOKUP(C10,SETUP!$A$9:$D$18,4,0),"⚠ Check SETUP")) | Y10: =IF(OR(I10="",M10=""),"",(M10-I10)/I10) | Z10: =IF(OR(I10="",N10=""),"",(N10-I10)/I10) | AA10: =IF(OR(I10="",O10=""),"",(O10-I10)/I10) | AB10: =IF(OR(Q10="",S10<>"",P10="",I10=""),"",IF(P10="Investor Override",IF(L10="","",(L10-I10)/I10),IF(P10="Offer 1",IF(M10="","",(M10-I10)/I10),IF(P10="Offer 2",IF(N10="","",(N10-I10)/I10),IF(P10="Offer 3",IF(O10="","",(O10-I10)/I10),"")))))
A11: Giovanna Augusto | B11: 2-2032 | C11: B1 | D11: 46213 | E11: =IF(D11="","",D11-90) | F11: =IF(D11="","",D11-60) | G11: =IF(D11="","",D11-30) | H11: 0 | I11: 1895 | J11: =IF(I11="","",IF(ABS(N11-W11)<=ABS(M11-W11),IF(ABS(N11-W11)<=ABS(O11-W11),"Offer 2","Offer 3"),IF(ABS(M11-W11)<=ABS(O11-W11),"Offer 1","Offer 3"))) | L11: =IF(OR(I11="",K11=""),"",CEILING(I11*(1+K11),5)) | M11: =IF(I11="","",IF(X11="Under",CEILING(MAX(I11*1.02,MIN(V11,W11)*0.95),5),CEILING(MAX(I11*1.03,MIN(V11,W11)*0.97),5))) | N11: =IF(I11="","",IF(X11="Under",CEILING(MAX(I11*1.03,(V11+W11)/2*0.96),5),CEILING(MAX(I11*1.05,(V11+W11)/2*0.98),5))) | O11: =IF(I11="","",IF(X11="Under",CEILING(MAX(I11*1.05,MIN(V11,W11*1.01)),5),CEILING(MAX(I11*1.08,MIN(V11,W11*1.02)),5))) | V11: =IF(C11="","",IFERROR(VLOOKUP(C11,SETUP!$A$9:$D$18,2,0),"⚠ Check SETUP")) | W11: =IF(C11="","",IFERROR(VLOOKUP(C11,SETUP!$A$9:$D$18,3,0),"⚠ Check SETUP")) | X11: =IF(C11="","",IFERROR(VLOOKUP(C11,SETUP!$A$9:$D$18,4,0),"⚠ Check SETUP")) | Y11: =IF(OR(I11="",M11=""),"",(M11-I11)/I11) | Z11: =IF(OR(I11="",N11=""),"",(N11-I11)/I11) | AA11: =IF(OR(I11="",O11=""),"",(O11-I11)/I11) | AB11: =IF(OR(Q11="",S11<>"",P11="",I11=""),"",IF(P11="Investor Override",IF(L11="","",(L11-I11)/I11),IF(P11="Offer 1",IF(M11="","",(M11-I11)/I11),IF(P11="Offer 2",IF(N11="","",(N11-I11)/I11),IF(P11="Offer 3",IF(O11="","",(O11-I11)/I11),"")))))
A12: Olvin Ponce | B12: 17-2327 | C12: C1 | D12: 46215 | E12: =IF(D12="","",D12-90) | F12: =IF(D12="","",D12-60) | G12: =IF(D12="","",D12-30) | H12: 500 | I12: 2395 | J12: =IF(I12="","",IF(ABS(N12-W12)<=ABS(M12-W12),IF(ABS(N12-W12)<=ABS(O12-W12),"Offer 2","Offer 3"),IF(ABS(M12-W12)<=ABS(O12-W12),"Offer 1","Offer 3"))) | L12: =IF(OR(I12="",K12=""),"",CEILING(I12*(1+K12),5)) | M12: =IF(I12="","",IF(X12="Under",CEILING(MAX(I12*1.02,MIN(V12,W12)*0.95),5),CEILING(MAX(I12*1.03,MIN(V12,W12)*0.97),5))) | N12: =IF(I12="","",IF(X12="Under",CEILING(MAX(I12*1.03,(V12+W12)/2*0.96),5),CEILING(MAX(I12*1.05,(V12+W12)/2*0.98),5))) | O12: =IF(I12="","",IF(X12="Under",CEILING(MAX(I12*1.05,MIN(V12,W12*1.01)),5),CEILING(MAX(I12*1.08,MIN(V12,W12*1.02)),5))) | V12: =IF(C12="","",IFERROR(VLOOKUP(C12,SETUP!$A$9:$D$18,2,0),"⚠ Check SETUP")) | W12: =IF(C12="","",IFERROR(VLOOKUP(C12,SETUP!$A$9:$D$18,3,0),"⚠ Check SETUP")) | X12: =IF(C12="","",IFERROR(VLOOKUP(C12,SETUP!$A$9:$D$18,4,0),"⚠ Check SETUP")) | Y12: =IF(OR(I12="",M12=""),"",(M12-I12)/I12) | Z12: =IF(OR(I12="",N12=""),"",(N12-I12)/I12) | AA12: =IF(OR(I12="",O12=""),"",(O12-I12)/I12) | AB12: =IF(OR(Q12="",S12<>"",P12="",I12=""),"",IF(P12="Investor Override",IF(L12="","",(L12-I12)/I12),IF(P12="Offer 1",IF(M12="","",(M12-I12)/I12),IF(P12="Offer 2",IF(N12="","",(N12-I12)/I12),IF(P12="Offer 3",IF(O12="","",(O12-I12)/I12),"")))))
A13: Orianna Raaz | B13: 3-2063 | C13: C1 | D13: 46228 | E13: =IF(D13="","",D13-90) | F13: =IF(D13="","",D13-60) | G13: =IF(D13="","",D13-30) | H13: 0 | I13: 2395 | J13: =IF(I13="","",IF(ABS(N13-W13)<=ABS(M13-W13),IF(ABS(N13-W13)<=ABS(O13-W13),"Offer 2","Offer 3"),IF(ABS(M13-W13)<=ABS(O13-W13),"Offer 1","Offer 3"))) | L13: =IF(OR(I13="",K13=""),"",CEILING(I13*(1+K13),5)) | M13: =IF(I13="","",IF(X13="Under",CEILING(MAX(I13*1.02,MIN(V13,W13)*0.95),5),CEILING(MAX(I13*1.03,MIN(V13,W13)*0.97),5))) | N13: =IF(I13="","",IF(X13="Under",CEILING(MAX(I13*1.03,(V13+W13)/2*0.96),5),CEILING(MAX(I13*1.05,(V13+W13)/2*0.98),5))) | O13: =IF(I13="","",IF(X13="Under",CEILING(MAX(I13*1.05,MIN(V13,W13*1.01)),5),CEILING(MAX(I13*1.08,MIN(V13,W13*1.02)),5))) | V13: =IF(C13="","",IFERROR(VLOOKUP(C13,SETUP!$A$9:$D$18,2,0),"⚠ Check SETUP")) | W13: =IF(C13="","",IFERROR(VLOOKUP(C13,SETUP!$A$9:$D$18,3,0),"⚠ Check SETUP")) | X13: =IF(C13="","",IFERROR(VLOOKUP(C13,SETUP!$A$9:$D$18,4,0),"⚠ Check SETUP")) | Y13: =IF(OR(I13="",M13=""),"",(M13-I13)/I13) | Z13: =IF(OR(I13="",N13=""),"",(N13-I13)/I13) | AA13: =IF(OR(I13="",O13=""),"",(O13-I13)/I13) | AB13: =IF(OR(Q13="",S13<>"",P13="",I13=""),"",IF(P13="Investor Override",IF(L13="","",(L13-I13)/I13),IF(P13="Offer 1",IF(M13="","",(M13-I13)/I13),IF(P13="Offer 2",IF(N13="","",(N13-I13)/I13),IF(P13="Offer 3",IF(O13="","",(O13-I13)/I13),"")))))
A14: Shermaine Scott | B14: 18-2361 | C14: C1 | D14: 46232 | E14: =IF(D14="","",D14-90) | F14: =IF(D14="","",D14-60) | G14: =IF(D14="","",D14-30) | H14: 0 | I14: 2195 | J14: =IF(I14="","",IF(ABS(N14-W14)<=ABS(M14-W14),IF(ABS(N14-W14)<=ABS(O14-W14),"Offer 2","Offer 3"),IF(ABS(M14-W14)<=ABS(O14-W14),"Offer 1","Offer 3"))) | L14: =IF(OR(I14="",K14=""),"",CEILING(I14*(1+K14),5)) | M14: =IF(I14="","",IF(X14="Under",CEILING(MAX(I14*1.02,MIN(V14,W14)*0.95),5),CEILING(MAX(I14*1.03,MIN(V14,W14)*0.97),5))) | N14: =IF(I14="","",IF(X14="Under",CEILING(MAX(I14*1.03,(V14+W14)/2*0.96),5),CEILING(MAX(I14*1.05,(V14+W14)/2*0.98),5))) | O14: =IF(I14="","",IF(X14="Under",CEILING(MAX(I14*1.05,MIN(V14,W14*1.01)),5),CEILING(MAX(I14*1.08,MIN(V14,W14*1.02)),5))) | V14: =IF(C14="","",IFERROR(VLOOKUP(C14,SETUP!$A$9:$D$18,2,0),"⚠ Check SETUP")) | W14: =IF(C14="","",IFERROR(VLOOKUP(C14,SETUP!$A$9:$D$18,3,0),"⚠ Check SETUP")) | X14: =IF(C14="","",IFERROR(VLOOKUP(C14,SETUP!$A$9:$D$18,4,0),"⚠ Check SETUP")) | Y14: =IF(OR(I14="",M14=""),"",(M14-I14)/I14) | Z14: =IF(OR(I14="",N14=""),"",(N14-I14)/I14) | AA14: =IF(OR(I14="",O14=""),"",(O14-I14)/I14) | AB14: =IF(OR(Q14="",S14<>"",P14="",I14=""),"",IF(P14="Investor Override",IF(L14="","",(L14-I14)/I14),IF(P14="Offer 1",IF(M14="","",(M14-I14)/I14),IF(P14="Offer 2",IF(N14="","",(N14-I14)/I14),IF(P14="Offer 3",IF(O14="","",(O14-I14)/I14),"")))))
A15: Deoveyon James | B15: 8-2160 | C15: C1 | D15: 46232 | E15: =IF(D15="","",D15-90) | F15: =IF(D15="","",D15-60) | G15: =IF(D15="","",D15-30) | H15: 0 | I15: 2095 | J15: =IF(I15="","",IF(ABS(N15-W15)<=ABS(M15-W15),IF(ABS(N15-W15)<=ABS(O15-W15),"Offer 2","Offer 3"),IF(ABS(M15-W15)<=ABS(O15-W15),"Offer 1","Offer 3"))) | L15: =IF(OR(I15="",K15=""),"",CEILING(I15*(1+K15),5)) | M15: =IF(I15="","",IF(X15="Under",CEILING(MAX(I15*1.02,MIN(V15,W15)*0.95),5),CEILING(MAX(I15*1.03,MIN(V15,W15)*0.97),5))) | N15: =IF(I15="","",IF(X15="Under",CEILING(MAX(I15*1.03,(V15+W15)/2*0.96),5),CEILING(MAX(I15*1.05,(V15+W15)/2*0.98),5))) | O15: =IF(I15="","",IF(X15="Under",CEILING(MAX(I15*1.05,MIN(V15,W15*1.01)),5),CEILING(MAX(I15*1.08,MIN(V15,W15*1.02)),5))) | V15: =IF(C15="","",IFERROR(VLOOKUP(C15,SETUP!$A$9:$D$18,2,0),"⚠ Check SETUP")) | W15: =IF(C15="","",IFERROR(VLOOKUP(C15,SETUP!$A$9:$D$18,3,0),"⚠ Check SETUP")) | X15: =IF(C15="","",IFERROR(VLOOKUP(C15,SETUP!$A$9:$D$18,4,0),"⚠ Check SETUP")) | Y15: =IF(OR(I15="",M15=""),"",(M15-I15)/I15) | Z15: =IF(OR(I15="",N15=""),"",(N15-I15)/I15) | AA15: =IF(OR(I15="",O15=""),"",(O15-I15)/I15) | AB15: =IF(OR(Q15="",S15<>"",P15="",I15=""),"",IF(P15="Investor Override",IF(L15="","",(L15-I15)/I15),IF(P15="Offer 1",IF(M15="","",(M15-I15)/I15),IF(P15="Offer 2",IF(N15="","",(N15-I15)/I15),IF(P15="Offer 3",IF(O15="","",(O15-I15)/I15),"")))))
... A17: Elienid Coke | B17: 18-2357 | C17: C1 | D17: 46234 | E17: =IF(D17="","",D17-90) | F17: =IF(D17="","",D17-60) | G17: =IF(D17="","",D17-30) | H17: 2195 | I17: 2195 | J17: =IF(I17="","",IF(ABS(N17-W17)<=ABS(M17-W17),IF(ABS(N17-W17)<=ABS(O17-W17),"Offer 2","Offer 3"),IF(ABS(M17-W17)<=ABS(O17-W17),"Offer 1","Offer 3"))) | L17: =IF(OR(I17="",K17=""),"",CEILING(I17*(1+K17),5)) | M17: =IF(I17="","",IF(X17="Under",CEILING(MAX(I17*1.02,MIN(V17,W17)*0.95),5),CEILING(MAX(I17*1.03,MIN(V17,W17)*0.97),5))) | N17: =IF(I17="","",IF(X17="Under",CEILING(MAX(I17*1.03,(V17+W17)/2*0.96),5),CEILING(MAX(I17*1.05,(V17+W17)/2*0.98),5))) | O17: =IF(I17="","",IF(X17="Under",CEILING(MAX(I17*1.05,MIN(V17,W17*1.01)),5),CEILING(MAX(I17*1.08,MIN(V17,W17*1.02)),5))) | V17: =IF(C17="","",IFERROR(VLOOKUP(C17,SETUP!$A$9:$D$18,2,0),"⚠ Check SETUP")) | W17: =IF(C17="","",IFERROR(VLOOKUP(C17,SETUP!$A$9:$D$18,3,0),"⚠ Check SETUP")) | X17: =IF(C17="","",IFERROR(VLOOKUP(C17,SETUP!$A$9:$D$18,4,0),"⚠ Check SETUP")) | Y17: =IF(OR(I17="",M17=""),"",(M17-I17)/I17) | Z17: =IF(OR(I17="",N17=""),"",(N17-I17)/I17) | AA17: =IF(OR(I17="",O17=""),"",(O17-I17)/I17) | AB17: =IF(OR(Q17="",S17<>"",P17="",I17=""),"",IF(P17="Investor Override",IF(L17="","",(L17-I17)/I17),IF(P17="Offer 1",IF(M17="","",(M17-I17)/I17),IF(P17="Offer 2",IF(N17="","",(N17-I17)/I17),IF(P17="Offer 3",IF(O17="","",(O17-I17)/I17),"")))))
E18: =IF(D18="","",D18-90) | F18: =IF(D18="","",D18-60) | G18: =IF(D18="","",D18-30) | J18: =IF(I18="","",IF(ABS(N18-W18)<=ABS(M18-W18),IF(ABS(N18-W18)<=ABS(O18-W18),"Offer 2","Offer 3"),IF(ABS(M18-W18)<=ABS(O18-W18),"Offer 1","Offer 3"))) | L18: =IF(OR(I18="",K18=""),"",CEILING(I18*(1+K18),5)) | M18: =IF(I18="","",IF(X18="Under",CEILING(MAX(I18*1.02,MIN(V18,W18)*0.95),5),CEILING(MAX(I18*1.03,MIN(V18,W18)*0.97),5))) | N18: =IF(I18="","",IF(X18="Under",CEILING(MAX(I18*1.03,(V18+W18)/2*0.96),5),CEILING(MAX(I18*1.05,(V18+W18)/2*0.98),5))) | O18: =IF(I18="","",IF(X18="Under",CEILING(MAX(I18*1.05,MIN(V18,W18*1.01)),5),CEILING(MAX(I18*1.08,MIN(V18,W18*1.02)),5))) | V18: =IF(C18="","",IFERROR(VLOOKUP(C18,SETUP!$A$9:$D$18,2,0),"⚠ Check SETUP")) | W18: =IF(C18="","",IFERROR(VLOOKUP(C18,SETUP!$A$9:$D$18,3,0),"⚠ Check SETUP")) | X18: =IF(C18="","",IFERROR(VLOOKUP(C18,SETUP!$A$9:$D$18,4,0),"⚠ Check SETUP")) | Y18: =IF(OR(I18="",M18=""),"",(M18-I18)/I18) | Z18: =IF(OR(I18="",N18=""),"",(N18-I18)/I18) | AA18: =IF(OR(I18="",O18=""),"",(O18-I18)/I18) | AB18: =IF(OR(Q18="",S18<>"",P18="",I18=""),"",IF(P18="Investor Override",IF(L18="","",(L18-I18)/I18),IF(P18="Offer 1",IF(M18="","",(M18-I18)/I18),IF(P18="Offer 2",IF(N18="","",(N18-I18)/I18),IF(P18="Offer 3",IF(O18="","",(O18-I18)/I18),"")))))
E19: =IF(D19="","",D19-90) | F19: =IF(D19="","",D19-60) | G19: =IF(D19="","",D19-30) | J19: =IF(I19="","",IF(ABS(N19-W19)<=ABS(M19-W19),IF(ABS(N19-W19)<=ABS(O19-W19),"Offer 2","Offer 3"),IF(ABS(M19-W19)<=ABS(O19-W19),"Offer 1","Offer 3"))) | L19: =IF(OR(I19="",K19=""),"",CEILING(I19*(1+K19),5)) | M19: =IF(I19="","",IF(X19="Under",CEILING(MAX(I19*1.02,MIN(V19,W19)*0.95),5),CEILING(MAX(I19*1.03,MIN(V19,W19)*0.97),5))) | N19: =IF(I19="","",IF(X19="Under",CEILING(MAX(I19*1.03,(V19+W19)/2*0.96),5),CEILING(MAX(I19*1.05,(V19+W19)/2*0.98),5))) | O19: =IF(I19="","",IF(X19="Under",CEILING(MAX(I19*1.05,MIN(V19,W19*1.01)),5),CEILING(MAX(I19*1.08,MIN(V19,W19*1.02)),5))) | V19: =IF(C19="","",IFERROR(VLOOKUP(C19,SETUP!$A$9:$D$18,2,0),"⚠ Check SETUP")) | W19: =IF(C19="","",IFERROR(VLOOKUP(C19,SETUP!$A$9:$D$18,3,0),"⚠ Check SETUP")) | X19: =IF(C19="","",IFERROR(VLOOKUP(C19,SETUP!$A$9:$D$18,4,0),"⚠ Check SETUP")) | Y19: =IF(OR(I19="",M19=""),"",(M19-I19)/I19) | Z19: =IF(OR(I19="",N19=""),"",(N19-I19)/I19) | AA19: =IF(OR(I19="",O19=""),"",(O19-I19)/I19) | AB19: =IF(OR(Q19="",S19<>"",P19="",I19=""),"",IF(P19="Investor Override",IF(L19="","",(L19-I19)/I19),IF(P19="Offer 1",IF(M19="","",(M19-I19)/I19),IF(P19="Offer 2",IF(N19="","",(N19-I19)/I19),IF(P19="Offer 3",IF(O19="","",(O19-I19)/I19),"")))))
E20: =IF(D20="","",D20-90) | F20: =IF(D20="","",D20-60) | G20: =IF(D20="","",D20-30) | J20: =IF(I20="","",IF(ABS(N20-W20)<=ABS(M20-W20),IF(ABS(N20-W20)<=ABS(O20-W20),"Offer 2","Offer 3"),IF(ABS(M20-W20)<=ABS(O20-W20),"Offer 1","Offer 3"))) | L20: =IF(OR(I20="",K20=""),"",CEILING(I20*(1+K20),5)) | M20: =IF(I20="","",IF(X20="Under",CEILING(MAX(I20*1.02,MIN(V20,W20)*0.95),5),CEILING(MAX(I20*1.03,MIN(V20,W20)*0.97),5))) | N20: =IF(I20="","",IF(X20="Under",CEILING(MAX(I20*1.03,(V20+W20)/2*0.96),5),CEILING(MAX(I20*1.05,(V20+W20)/2*0.98),5))) | O20: =IF(I20="","",IF(X20="Under",CEILING(MAX(I20*1.05,MIN(V20,W20*1.01)),5),CEILING(MAX(I20*1.08,MIN(V20,W20*1.02)),5))) | V20: =IF(C20="","",IFERROR(VLOOKUP(C20,SETUP!$A$9:$D$18,2,0),"⚠ Check SETUP")) | W20: =IF(C20="","",IFERROR(VLOOKUP(C20,SETUP!$A$9:$D$18,3,0),"⚠ Check SETUP")) | X20: =IF(C20="","",IFERROR(VLOOKUP(C20,SETUP!$A$9:$D$18,4,0),"⚠ Check SETUP")) | Y20: =IF(OR(I20="",M20=""),"",(M20-I20)/I20) | Z20: =IF(OR(I20="",N20=""),"",(N20-I20)/I20) | AA20: =IF(OR(I20="",O20=""),"",(O20-I20)/I20) | AB20: =IF(OR(Q20="",S20<>"",P20="",I20=""),"",IF(P20="Investor Override",IF(L20="","",(L20-I20)/I20),IF(P20="Offer 1",IF(M20="","",(M20-I20)/I20),IF(P20="Offer 2",IF(N20="","",(N20-I20)/I20),IF(P20="Offer 3",IF(O20="","",(O20-I20)/I20),"")))))
E21: =IF(D21="","",D21-90) | F21: =IF(D21="","",D21-60) | G21: =IF(D21="","",D21-30) | J21: =IF(I21="","",IF(ABS(N21-W21)<=ABS(M21-W21),IF(ABS(N21-W21)<=ABS(O21-W21),"Offer 2","Offer 3"),IF(ABS(M21-W21)<=ABS(O21-W21),"Offer 1","Offer 3"))) | L21: =IF(OR(I21="",K21=""),"",CEILING(I21*(1+K21),5)) | M21: =IF(I21="","",IF(X21="Under",CEILING(MAX(I21*1.02,MIN(V21,W21)*0.95),5),CEILING(MAX(I21*1.03,MIN(V21,W21)*0.97),5))) | N21: =IF(I21="","",IF(X21="Under",CEILING(MAX(I21*1.03,(V21+W21)/2*0.96),5),CEILING(MAX(I21*1.05,(V21+W21)/2*0.98),5))) | O21: =IF(I21="","",IF(X21="Under",CEILING(MAX(I21*1.05,MIN(V21,W21*1.01)),5),CEILING(MAX(I21*1.08,MIN(V21,W21*1.02)),5))) | V21: =IF(C21="","",IFERROR(VLOOKUP(C21,SETUP!$A$9:$D$18,2,0),"⚠ Check SETUP")) | W21: =IF(C21="","",IFERROR(VLOOKUP(C21,SETUP!$A$9:$D$18,3,0),"⚠ Check SETUP")) | X21: =IF(C21="","",IFERROR(VLOOKUP(C21,SETUP!$A$9:$D$18,4,0),"⚠ Check SETUP")) | Y21: =IF(OR(I21="",M21=""),"",(M21-I21)/I21) | Z21: =IF(OR(I21="",N21=""),"",(N21-I21)/I21) | AA21: =IF(OR(I21="",O21=""),"",(O21-I21)/I21) | AB21: =IF(OR(Q21="",S21<>"",P21="",I21=""),"",IF(P21="Investor Override",IF(L21="","",(L21-I21)/I21),IF(P21="Offer 1",IF(M21="","",(M21-I21)/I21),IF(P21="Offer 2",IF(N21="","",(N21-I21)/I21),IF(P21="Offer 3",IF(O21="","",(O21-I21)/I21),"")))))
E22: =IF(D22="","",D22-90) | F22: =IF(D22="","",D22-60) | G22: =IF(D22="","",D22-30) | J22: =IF(I22="","",IF(ABS(N22-W22)<=ABS(M22-W22),IF(ABS(N22-W22)<=ABS(O22-W22),"Offer 2","Offer 3"),IF(ABS(M22-W22)<=ABS(O22-W22),"Offer 1","Offer 3"))) | L22: =IF(OR(I22="",K22=""),"",CEILING(I22*(1+K22),5)) | M22: =IF(I22="","",IF(X22="Under",CEILING(MAX(I22*1.02,MIN(V22,W22)*0.95),5),CEILING(MAX(I22*1.03,MIN(V22,W22)*0.97),5))) | N22: =IF(I22="","",IF(X22="Under",CEILING(MAX(I22*1.03,(V22+W22)/2*0.96),5),CEILING(MAX(I22*1.05,(V22+W22)/2*0.98),5))) | O22: =IF(I22="","",IF(X22="Under",CEILING(MAX(I22*1.05,MIN(V22,W22*1.01)),5),CEILING(MAX(I22*1.08,MIN(V22,W22*1.02)),5))) | V22: =IF(C22="","",IFERROR(VLOOKUP(C22,SETUP!$A$9:$D$18,2,0),"⚠ Check SETUP")) | W22: =IF(C22="","",IFERROR(VLOOKUP(C22,SETUP!$A$9:$D$18,3,0),"⚠ Check SETUP")) | X22: =IF(C22="","",IFERROR(VLOOKUP(C22,SETUP!$A$9:$D$18,4,0),"⚠ Check SETUP")) | Y22: =IF(OR(I22="",M22=""),"",(M22-I22)/I22) | Z22: =IF(OR(I22="",N22=""),"",(N22-I22)/I22) | AA22: =IF(OR(I22="",O22=""),"",(O22-I22)/I22) | AB22: =IF(OR(Q22="",S22<>"",P22="",I22=""),"",IF(P22="Investor Override",IF(L22="","",(L22-I22)/I22),IF(P22="Offer 1",IF(M22="","",(M22-I22)/I22),IF(P22="Offer 2",IF(N22="","",(N22-I22)/I22),IF(P22="Offer 3",IF(O22="","",(O22-I22)/I22),"")))))
E23: =IF(D23="","",D23-90) | F23: =IF(D23="","",D23-60) | G23: =IF(D23="","",D23-30) | J23: =IF(I23="","",IF(ABS(N23-W23)<=ABS(M23-W23),IF(ABS(N23-W23)<=ABS(O23-W23),"Offer 2","Offer 3"),IF(ABS(M23-W23)<=ABS(O23-W23),"Offer 1","Offer 3"))) | L23: =IF(OR(I23="",K23=""),"",CEILING(I23*(1+K23),5)) | M23: =IF(I23="","",IF(X23="Under",CEILING(MAX(I23*1.02,MIN(V23,W23)*0.95),5),CEILING(MAX(I23*1.03,MIN(V23,W23)*0.97),5))) | N23: =IF(I23="","",IF(X23="Under",CEILING(MAX(I23*1.03,(V23+W23)/2*0.96),5),CEILING(MAX(I23*1.05,(V23+W23)/2*0.98),5))) | O23: =IF(I23="","",IF(X23="Under",CEILING(MAX(I23*1.05,MIN(V23,W23*1.01)),5),CEILING(MAX(I23*1.08,MIN(V23,W23*1.02)),5))) | V23: =IF(C23="","",IFERROR(VLOOKUP(C23,SETUP!$A$9:$D$18,2,0),"⚠ Check SETUP")) | W23: =IF(C23="","",IFERROR(VLOOKUP(C23,SETUP!$A$9:$D$18,3,0),"⚠ Check SETUP")) | X23: =IF(C23="","",IFERROR(VLOOKUP(C23,SETUP!$A$9:$D$18,4,0),"⚠ Check SETUP")) | Y23: =IF(OR(I23="",M23=""),"",(M23-I23)/I23) | Z23: =IF(OR(I23="",N23=""),"",(N23-I23)/I23) | AA23: =IF(OR(I23="",O23=""),"",(O23-I23)/I23) | AB23: =IF(OR(Q23="",S23<>"",P23="",I23=""),"",IF(P23="Investor Override",IF(L23="","",(L23-I23)/I23),IF(P23="Offer 1",IF(M23="","",(M23-I23)/I23),IF(P23="Offer 2",IF(N23="","",(N23-I23)/I23),IF(P23="Offer 3",IF(O23="","",(O23-I23)/I23),"")))))
E24: =IF(D24="","",D24-90) | F24: =IF(D24="","",D24-60) | G24: =IF(D24="","",D24-30) | J24: =IF(I24="","",IF(ABS(N24-W24)<=ABS(M24-W24),IF(ABS(N24-W24)<=ABS(O24-W24),"Offer 2","Offer 3"),IF(ABS(M24-W24)<=ABS(O24-W24),"Offer 1","Offer 3"))) | L24: =IF(OR(I24="",K24=""),"",CEILING(I24*(1+K24),5)) | M24: =IF(I24="","",IF(X24="Under",CEILING(MAX(I24*1.02,MIN(V24,W24)*0.95),5),CEILING(MAX(I24*1.03,MIN(V24,W24)*0.97),5))) | N24: =IF(I24="","",IF(X24="Under",CEILING(MAX(I24*1.03,(V24+W24)/2*0.96),5),CEILING(MAX(I24*1.05,(V24+W24)/2*0.98),5))) | O24: =IF(I24="","",IF(X24="Under",CEILING(MAX(I24*1.05,MIN(V24,W24*1.01)),5),CEILING(MAX(I24*1.08,MIN(V24,W24*1.02)),5))) | V24: =IF(C24="","",IFERROR(VLOOKUP(C24,SETUP!$A$9:$D$18,2,0),"⚠ Check SETUP")) | W24: =IF(C24="","",IFERROR(VLOOKUP(C24,SETUP!$A$9:$D$18,3,0),"⚠ Check SETUP")) | X24: =IF(C24="","",IFERROR(VLOOKUP(C24,SETUP!$A$9:$D$18,4,0),"⚠ Check SETUP")) | Y24: =IF(OR(I24="",M24=""),"",(M24-I24)/I24) | Z24: =IF(OR(I24="",N24=""),"",(N24-I24)/I24) | AA24: =IF(OR(I24="",O24=""),"",(O24-I24)/I24) | AB24: =IF(OR(Q24="",S24<>"",P24="",I24=""),"",IF(P24="Investor Override",IF(L24="","",(L24-I24)/I24),IF(P24="Offer 1",IF(M24="","",(M24-I24)/I24),IF(P24="Offer 2",IF(N24="","",(N24-I24)/I24),IF(P24="Offer 3",IF(O24="","",(O24-I24)/I24),"")))))
E25: =IF(D25="","",D25-90) | F25: =IF(D25="","",D25-60) | G25: =IF(D25="","",D25-30) | J25: =IF(I25="","",IF(ABS(N25-W25)<=ABS(M25-W25),IF(ABS(N25-W25)<=ABS(O25-W25),"Offer 2","Offer 3"),IF(ABS(M25-W25)<=ABS(O25-W25),"Offer 1","Offer 3"))) | L25: =IF(OR(I25="",K25=""),"",CEILING(I25*(1+K25),5)) | M25: =IF(I25="","",IF(X25="Under",CEILING(MAX(I25*1.02,MIN(V25,W25)*0.95),5),CEILING(MAX(I25*1.03,MIN(V25,W25)*0.97),5))) | N25: =IF(I25="","",IF(X25="Under",CEILING(MAX(I25*1.03,(V25+W25)/2*0.96),5),CEILING(MAX(I25*1.05,(V25+W25)/2*0.98),5))) | O25: =IF(I25="","",IF(X25="Under",CEILING(MAX(I25*1.05,MIN(V25,W25*1.01)),5),CEILING(MAX(I25*1.08,MIN(V25,W25*1.02)),5))) | V25: =IF(C25="","",IFERROR(VLOOKUP(C25,SETUP!$A$9:$D$18,2,0),"⚠ Check SETUP")) | W25: =IF(C25="","",IFERROR(VLOOKUP(C25,SETUP!$A$9:$D$18,3,0),"⚠ Check SETUP")) | X25: =IF(C25="","",IFERROR(VLOOKUP(C25,SETUP!$A$9:$D$18,4,0),"⚠ Check SETUP")) | Y25: =IF(OR(I25="",M25=""),"",(M25-I25)/I25) | Z25: =IF(OR(I25="",N25=""),"",(N25-I25)/I25) | AA25: =IF(OR(I25="",O25=""),"",(O25-I25)/I25) | AB25: =IF(OR(Q25="",S25<>"",P25="",I25=""),"",IF(P25="Investor Override",IF(L25="","",(L25-I25)/I25),IF(P25="Offer 1",IF(M25="","",(M25-I25)/I25),IF(P25="Offer 2",IF(N25="","",(N25-I25)/I25),IF(P25="Offer 3",IF(O25="","",(O25-I25)/I25),"")))))
E26: =IF(D26="","",D26-90) | F26: =IF(D26="","",D26-60) | G26: =IF(D26="","",D26-30) | J26: =IF(I26="","",IF(ABS(N26-W26)<=ABS(M26-W26),IF(ABS(N26-W26)<=ABS(O26-W26),"Offer 2","Offer 3"),IF(ABS(M26-W26)<=ABS(O26-W26),"Offer 1","Offer 3"))) | L26: =IF(OR(I26="",K26=""),"",CEILING(I26*(1+K26),5)) | M26: =IF(I26="","",IF(X26="Under",CEILING(MAX(I26*1.02,MIN(V26,W26)*0.95),5),CEILING(MAX(I26*1.03,MIN(V26,W26)*0.97),5))) | N26: =IF(I26="","",IF(X26="Under",CEILING(MAX(I26*1.03,(V26+W26)/2*0.96),5),CEILING(MAX(I26*1.05,(V26+W26)/2*0.98),5))) | O26: =IF(I26="","",IF(X26="Under",CEILING(MAX(I26*1.05,MIN(V26,W26*1.01)),5),CEILING(MAX(I26*1.08,MIN(V26,W26*1.02)),5))) | V26: =IF(C26="","",IFERROR(VLOOKUP(C26,SETUP!$A$9:$D$18,2,0),"⚠ Check SETUP")) | W26: =IF(C26="","",IFERROR(VLOOKUP(C26,SETUP!$A$9:$D$18,3,0),"⚠ Check SETUP")) | X26: =IF(C26="","",IFERROR(VLOOKUP(C26,SETUP!$A$9:$D$18,4,0),"⚠ Check SETUP")) | Y26: =IF(OR(I26="",M26=""),"",(M26-I26)/I26) | Z26: =IF(OR(I26="",N26=""),"",(N26-I26)/I26) | AA26: =IF(OR(I26="",O26=""),"",(O26-I26)/I26) | AB26: =IF(OR(Q26="",S26<>"",P26="",I26=""),"",IF(P26="Investor Override",IF(L26="","",(L26-I26)/I26),IF(P26="Offer 1",IF(M26="","",(M26-I26)/I26),IF(P26="Offer 2",IF(N26="","",(N26-I26)/I26),IF(P26="Offer 3",IF(O26="","",(O26-I26)/I26),"")))))
E27: =IF(D27="","",D27-90) | F27: =IF(D27="","",D27-60) | G27: =IF(D27="","",D27-30) | J27: =IF(I27="","",IF(ABS(N27-W27)<=ABS(M27-W27),IF(ABS(N27-W27)<=ABS(O27-W27),"Offer 2","Offer 3"),IF(ABS(M27-W27)<=ABS(O27-W27),"Offer 1","Offer 3"))) | L27: =IF(OR(I27="",K27=""),"",CEILING(I27*(1+K27),5)) | M27: =IF(I27="","",IF(X27="Under",CEILING(MAX(I27*1.02,MIN(V27,W27)*0.95),5),CEILING(MAX(I27*1.03,MIN(V27,W27)*0.97),5))) | N27: =IF(I27="","",IF(X27="Under",CEILING(MAX(I27*1.03,(V27+W27)/2*0.96),5),CEILING(MAX(I27*1.05,(V27+W27)/2*0.98),5))) | O27: =IF(I27="","",IF(X27="Under",CEILING(MAX(I27*1.05,MIN(V27,W27*1.01)),5),CEILING(MAX(I27*1.08,MIN(V27,W27*1.02)),5))) | V27: =IF(C27="","",IFERROR(VLOOKUP(C27,SETUP!$A$9:$D$18,2,0),"⚠ Check SETUP")) | W27: =IF(C27="","",IFERROR(VLOOKUP(C27,SETUP!$A$9:$D$18,3,0),"⚠ Check SETUP")) | X27: =IF(C27="","",IFERROR(VLOOKUP(C27,SETUP!$A$9:$D$18,4,0),"⚠ Check SETUP")) | Y27: =IF(OR(I27="",M27=""),"",(M27-I27)/I27) | Z27: =IF(OR(I27="",N27=""),"",(N27-I27)/I27) | AA27: =IF(OR(I27="",O27=""),"",(O27-I27)/I27) | AB27: =IF(OR(Q27="",S27<>"",P27="",I27=""),"",IF(P27="Investor Override",IF(L27="","",(L27-I27)/I27),IF(P27="Offer 1",IF(M27="","",(M27-I27)/I27),IF(P27="Offer 2",IF(N27="","",(N27-I27)/I27),IF(P27="Offer 3",IF(O27="","",(O27-I27)/I27),"")))))
E28: =IF(D28="","",D28-90) | F28: =IF(D28="","",D28-60) | G28: =IF(D28="","",D28-30) | J28: =IF(I28="","",IF(ABS(N28-W28)<=ABS(M28-W28),IF(ABS(N28-W28)<=ABS(O28-W28),"Offer 2","Offer 3"),IF(ABS(M28-W28)<=ABS(O28-W28),"Offer 1","Offer 3"))) | L28: =IF(OR(I28="",K28=""),"",CEILING(I28*(1+K28),5)) | M28: =IF(I28="","",IF(X28="Under",CEILING(MAX(I28*1.02,MIN(V28,W28)*0.95),5),CEILING(MAX(I28*1.03,MIN(V28,W28)*0.97),5))) | N28: =IF(I28="","",IF(X28="Under",CEILING(MAX(I28*1.03,(V28+W28)/2*0.96),5),CEILING(MAX(I28*1.05,(V28+W28)/2*0.98),5))) | O28: =IF(I28="","",IF(X28="Under",CEILING(MAX(I28*1.05,MIN(V28,W28*1.01)),5),CEILING(MAX(I28*1.08,MIN(V28,W28*1.02)),5))) | V28: =IF(C28="","",IFERROR(VLOOKUP(C28,SETUP!$A$9:$D$18,2,0),"⚠ Check SETUP")) | W28: =IF(C28="","",IFERROR(VLOOKUP(C28,SETUP!$A$9:$D$18,3,0),"⚠ Check SETUP")) | X28: =IF(C28="","",IFERROR(VLOOKUP(C28,SETUP!$A$9:$D$18,4,0),"⚠ Check SETUP")) | Y28: =IF(OR(I28="",M28=""),"",(M28-I28)/I28) | Z28: =IF(OR(I28="",N28=""),"",(N28-I28)/I28) | AA28: =IF(OR(I28="",O28=""),"",(O28-I28)/I28) | AB28: =IF(OR(Q28="",S28<>"",P28="",I28=""),"",IF(P28="Investor Override",IF(L28="","",(L28-I28)/I28),IF(P28="Offer 1",IF(M28="","",(M28-I28)/I28),IF(P28="Offer 2",IF(N28="","",(N28-I28)/I28),IF(P28="Offer 3",IF(O28="","",(O28-I28)/I28),"")))))
E29: =IF(D29="","",D29-90) | F29: =IF(D29="","",D29-60) | G29: =IF(D29="","",D29-30) | J29: =IF(I29="","",IF(ABS(N29-W29)<=ABS(M29-W29),IF(ABS(N29-W29)<=ABS(O29-W29),"Offer 2","Offer 3"),IF(ABS(M29-W29)<=ABS(O29-W29),"Offer 1","Offer 3"))) | L29: =IF(OR(I29="",K29=""),"",CEILING(I29*(1+K29),5)) | M29: =IF(I29="","",IF(X29="Under",CEILING(MAX(I29*1.02,MIN(V29,W29)*0.95),5),CEILING(MAX(I29*1.03,MIN(V29,W29)*0.97),5))) | N29: =IF(I29="","",IF(X29="Under",CEILING(MAX(I29*1.03,(V29+W29)/2*0.96),5),CEILING(MAX(I29*1.05,(V29+W29)/2*0.98),5))) | O29: =IF(I29="","",IF(X29="Under",CEILING(MAX(I29*1.05,MIN(V29,W29*1.01)),5),CEILING(MAX(I29*1.08,MIN(V29,W29*1.02)),5))) | V29: =IF(C29="","",IFERROR(VLOOKUP(C29,SETUP!$A$9:$D$18,2,0),"⚠ Check SETUP")) | W29: =IF(C29="","",IFERROR(VLOOKUP(C29,SETUP!$A$9:$D$18,3,0),"⚠ Check SETUP")) | X29: =IF(C29="","",IFERROR(VLOOKUP(C29,SETUP!$A$9:$D$18,4,0),"⚠ Check SETUP")) | Y29: =IF(OR(I29="",M29=""),"",(M29-I29)/I29) | Z29: =IF(OR(I29="",N29=""),"",(N29-I29)/I29) | AA29: =IF(OR(I29="",O29=""),"",(O29-I29)/I29) | AB29: =IF(OR(Q29="",S29<>"",P29="",I29=""),"",IF(P29="Investor Override",IF(L29="","",(L29-I29)/I29),IF(P29="Offer 1",IF(M29="","",(M29-I29)/I29),IF(P29="Offer 2",IF(N29="","",(N29-I29)/I29),IF(P29="Offer 3",IF(O29="","",(O29-I29)/I29),"")))))
... E33: =IF(D33="","",D33-90) | F33: =IF(D33="","",D33-60) | G33: =IF(D33="","",D33-30) | J33: =IF(I33="","",IF(ABS(N33-W33)<=ABS(M33-W33),IF(ABS(N33-W33)<=ABS(O33-W33),"Offer 2","Offer 3"),IF(ABS(M33-W33)<=ABS(O33-W33),"Offer 1","Offer 3"))) | L33: =IF(OR(I33="",K33=""),"",CEILING(I33*(1+K33),5)) | M33: =IF(I33="","",IF(X33="Under",CEILING(MAX(I33*1.02,MIN(V33,W33)*0.95),5),CEILING(MAX(I33*1.03,MIN(V33,W33)*0.97),5))) | N33: =IF(I33="","",IF(X33="Under",CEILING(MAX(I33*1.03,(V33+W33)/2*0.96),5),CEILING(MAX(I33*1.05,(V33+W33)/2*0.98),5))) | O33: =IF(I33="","",IF(X33="Under",CEILING(MAX(I33*1.05,MIN(V33,W33*1.01)),5),CEILING(MAX(I33*1.08,MIN(V33,W33*1.02)),5))) | V33: =IF(C33="","",IFERROR(VLOOKUP(C33,SETUP!$A$9:$D$18,2,0),"⚠ Check SETUP")) | W33: =IF(C33="","",IFERROR(VLOOKUP(C33,SETUP!$A$9:$D$18,3,0),"⚠ Check SETUP")) | X33: =IF(C33="","",IFERROR(VLOOKUP(C33,SETUP!$A$9:$D$18,4,0),"⚠ Check SETUP")) | Y33: =IF(OR(I33="",M33=""),"",(M33-I33)/I33) | Z33: =IF(OR(I33="",N33=""),"",(N33-I33)/I33) | AA33: =IF(OR(I33="",O33=""),"",(O33-I33)/I33) | AB33: =IF(OR(Q33="",S33<>"",P33="",I33=""),"",IF(P33="Investor Override",IF(L33="","",(L33-I33)/I33),IF(P33="Offer 1",IF(M33="","",(M33-I33)/I33),IF(P33="Offer 2",IF(N33="","",(N33-I33)/I33),IF(P33="Offer 3",IF(O33="","",(O33-I33)/I33),"")))))
X34: Portfolio Avg (Excl. NTV) → | Y34: =IFERROR(AVERAGEIFS(Y4:Y33,S4:S33,""),"") | Z34: =IFERROR(AVERAGEIFS(Z4:Z33,S4:S33,""),"") | AA34: =IFERROR(AVERAGEIFS(AA4:AA33,S4:S33,""),"") | AB34: =IFERROR(AVERAGEIF(AB4:AB33,"<>"),"")
A36: RETENTION ANALYSIS
A37: Metric | B37: Count | C37: % of Expirations | D37: % of Decided | E37: Status
A38: Total Lease Expirations | B38: =COUNTA(A4:A33)
A39: Renewals Signed | B39: =COUNTA(Q4:Q33) | C39: =IFERROR(B39/B38,"-") | D39: =IFERROR(B39/(B39+B40),"-") | E39: =IF(B38=0,"Awaiting data",IF(B39/B38>=0.6,"On Track ✓","Needs Attention ⚠"))
A40: NTV's Received | B40: =COUNTA(S4:S33) | C40: =IFERROR(B40/B38,"-") | D40: =IFERROR(B40/(B39+B40),"-") | E40: =IF(B38=0,"Awaiting data",IF(B40/B38<=0.2,"Acceptable","High NTV ⚠"))
A41: Transfers | B41: =COUNTA(R4:R33) | C41: =IFERROR(B41/B38,"-") | D41: — | E41: Resident retained in portfolio
A42: Pending / Not Yet Decided | B42: =MAX(0,B38-B39-B40-B41) | C42: =IFERROR(B42/B38,"-") | D42: — | E42: =IF(B42=0,"All accounted for ✓","Follow up needed")
A44: RETENTION RATE (Renewals ÷ Total Expirations) | C44: =IFERROR(B39/B38,"-") | D44: =IF(B38=0,"Enter resident data to calculate",IF(B39/B38>=0.6,"✓ Meeting target retention","⚠ Below target — review offers"))
A45: RETENTION RATE (Renewals ÷ Renewals + NTVs) ← of decided residents | C45: =IFERROR(B39/(B39+B40),"-") | D45: Excludes pending residents — only counts those who have made a decision (renewed or NTV'd)
A48: Legend
...

Sheet TEMPLATE
A1: =SETUP!B3&" - "&SETUP!B4&" Renewals"
A2: Name | B2: Unit | C2: Unit Type | D2: Expiration Date | E2: 90-Day Notice | F2: 60-Day Notice | G2: 30-Day Notice | H2: Deposit Held | I2: Current Rate | J2: Recommended Offer | K2: Investor Override % Increase | L2: Investor Override Offer | M2: Offer 1 Conservative | N2: Offer 2 Balanced | O2: Offer 3 Aggressive | P2: Signed Offer | Q2: Renewal Signed | R2: Transfer | S2: NTV Rcv'd | T2: Phone | U2: Notes | V2: Market Rate | W2: Budget | X2: Occupancy (Under/Over) | Y2: Rent Growth Offer 1 | Z2: Rent Growth Offer 2 | AA2: Rent Growth Offer 3 | AB2: Signed Rent Growth
A3: ▼ Enter | B3: ▼ Enter | C3: ▼ Enter | D3: ▼ Enter | E3: ◀ Auto | F3: ◀ Auto | G3: ◀ Auto | H3: ▼ Enter | I3: ▼ Enter | J3: ◀ Auto | K3: ▼ Enter | L3: ◀ Auto | M3: ◀ Auto | N3: ◀ Auto | O3: ◀ Auto | P3: ▼ Select | Q3: ▼ Enter | R3: ▼ Enter | S3: ▼ Enter | T3: ▼ Enter | U3: ▼ Enter | V3: ◀ Auto | W3: ◀ Auto | X3: ◀ Auto | Y3: ◀ Auto | Z3: ◀ Auto | AA3: ◀ Auto | AB3: ◀ Auto
E4: =IF(D4="","",D4-90) | F4: =IF(D4="","",D4-60) | G4: =IF(D4="","",D4-30) | J4: =IF(I4="","",IF(ABS(N4-W4)<=ABS(M4-W4),IF(ABS(N4-W4)<=ABS(O4-W4),"Offer 2","Offer 3"),IF(ABS(M4-W4)<=ABS(O4-W4),"Offer 1","Offer 3"))) | L4: =IF(OR(I4="",K4=""),"",CEILING(I4*(1+K4),5)) | M4: =IF(I4="","",IF(X4="Under",CEILING(MAX(I4*1.02,MIN(V4,W4)*0.95),5),CEILING(MAX(I4*1.03,MIN(V4,W4)*0.97),5))) | N4: =IF(I4="","",IF(X4="Under",CEILING(MAX(I4*1.03,(V4+W4)/2*0.96),5),CEILING(MAX(I4*1.05,(V4+W4)/2*0.98),5))) | O4: =IF(I4="","",IF(X4="Under",CEILING(MAX(I4*1.05,MIN(V4,W4*1.01)),5),CEILING(MAX(I4*1.08,MIN(V4,W4*1.02)),5))) | V4: =IF(C4="","",IFERROR(VLOOKUP(C4,SETUP!$A$9:$D$18,2,0),"⚠ Check SETUP")) | W4: =IF(C4="","",IFERROR(VLOOKUP(C4,SETUP!$A$9:$D$18,3,0),"⚠ Check SETUP")) | X4: =IF(C4="","",IFERROR(VLOOKUP(C4,SETUP!$A$9:$D$18,4,0),"⚠ Check SETUP")) | Y4: =IF(OR(I4="",M4=""),"",(M4-I4)/I4) | Z4: =IF(OR(I4="",N4=""),"",(N4-I4)/I4) | AA4: =IF(OR(I4="",O4=""),"",(O4-I4)/I4) | AB4: =IF(OR(Q4="",S4<>"",P4="",I4=""),"",IF(P4="Investor Override",IF(L4="","",(L4-I4)/I4),IF(P4="Offer 1",IF(M4="","",(M4-I4)/I4),IF(P4="Offer 2",IF(N4="","",(N4-I4)/I4),IF(P4="Offer 3",IF(O4="","",(O4-I4)/I4),"")))))
E5: =IF(D5="","",D5-90) | F5: =IF(D5="","",D5-60) | G5: =IF(D5="","",D5-30) | J5: =IF(I5="","",IF(ABS(N5-W5)<=ABS(M5-W5),IF(ABS(N5-W5)<=ABS(O5-W5),"Offer 2","Offer 3"),IF(ABS(M5-W5)<=ABS(O5-W5),"Offer 1","Offer 3"))) | L5: =IF(OR(I5="",K5=""),"",CEILING(I5*(1+K5),5)) | M5: =IF(I5="","",IF(X5="Under",CEILING(MAX(I5*1.02,MIN(V5,W5)*0.95),5),CEILING(MAX(I5*1.03,MIN(V5,W5)*0.97),5))) | N5: =IF(I5="","",IF(X5="Under",CEILING(MAX(I5*1.03,(V5+W5)/2*0.96),5),CEILING(MAX(I5*1.05,(V5+W5)/2*0.98),5))) | O5: =IF(I5="","",IF(X5="Under",CEILING(MAX(I5*1.05,MIN(V5,W5*1.01)),5),CEILING(MAX(I5*1.08,MIN(V5,W5*1.02)),5))) | V5: =IF(C5="","",IFERROR(VLOOKUP(C5,SETUP!$A$9:$D$18,2,0),"⚠ Check SETUP")) | W5: =IF(C5="","",IFERROR(VLOOKUP(C5,SETUP!$A$9:$D$18,3,0),"⚠ Check SETUP")) | X5: =IF(C5="","",IFERROR(VLOOKUP(C5,SETUP!$A$9:$D$18,4,0),"⚠ Check SETUP")) | Y5: =IF(OR(I5="",M5=""),"",(M5-I5)/I5) | Z5: =IF(OR(I5="",N5=""),"",(N5-I5)/I5) | AA5: =IF(OR(I5="",O5=""),"",(O5-I5)/I5) | AB5: =IF(OR(Q5="",S5<>"",P5="",I5=""),"",IF(P5="Investor Override",IF(L5="","",(L5-I5)/I5),IF(P5="Offer 1",IF(M5="","",(M5-I5)/I5),IF(P5="Offer 2",IF(N5="","",(N5-I5)/I5),IF(P5="Offer 3",IF(O5="","",(O5-I5)/I5),"")))))
E6: =IF(D6="","",D6-90) | F6: =IF(D6="","",D6-60) | G6: =IF(D6="","",D6-30) | J6: =IF(I6="","",IF(ABS(N6-W6)<=ABS(M6-W6),IF(ABS(N6-W6)<=ABS(O6-W6),"Offer 2","Offer 3"),IF(ABS(M6-W6)<=ABS(O6-W6),"Offer 1","Offer 3"))) | L6: =IF(OR(I6="",K6=""),"",CEILING(I6*(1+K6),5)) | M6: =IF(I6="","",IF(X6="Under",CEILING(MAX(I6*1.02,MIN(V6,W6)*0.95),5),CEILING(MAX(I6*1.03,MIN(V6,W6)*0.97),5))) | N6: =IF(I6="","",IF(X6="Under",CEILING(MAX(I6*1.03,(V6+W6)/2*0.96),5),CEILING(MAX(I6*1.05,(V6+W6)/2*0.98),5))) | O6: =IF(I6="","",IF(X6="Under",CEILING(MAX(I6*1.05,MIN(V6,W6*1.01)),5),CEILING(MAX(I6*1.08,MIN(V6,W6*1.02)),5))) | V6: =IF(C6="","",IFERROR(VLOOKUP(C6,SETUP!$A$9:$D$18,2,0),"⚠ Check SETUP")) | W6: =IF(C6="","",IFERROR(VLOOKUP(C6,SETUP!$A$9:$D$18,3,0),"⚠ Check SETUP")) | X6: =IF(C6="","",IFERROR(VLOOKUP(C6,SETUP!$A$9:$D$18,4,0),"⚠ Check SETUP")) | Y6: =IF(OR(I6="",M6=""),"",(M6-I6)/I6) | Z6: =IF(OR(I6="",N6=""),"",(N6-I6)/I6) | AA6: =IF(OR(I6="",O6=""),"",(O6-I6)/I6) | AB6: =IF(OR(Q6="",S6<>"",P6="",I6=""),"",IF(P6="Investor Override",IF(L6="","",(L6-I6)/I6),IF(P6="Offer 1",IF(M6="","",(M6-I6)/I6),IF(P6="Offer 2",IF(N6="","",(N6-I6)/I6),IF(P6="Offer 3",IF(O6="","",(O6-I6)/I6),"")))))
E7: =IF(D7="","",D7-90) | F7: =IF(D7="","",D7-60) | G7: =IF(D7="","",D7-30) | J7: =IF(I7="","",IF(ABS(N7-W7)<=ABS(M7-W7),IF(ABS(N7-W7)<=ABS(O7-W7),"Offer 2","Offer 3"),IF(ABS(M7-W7)<=ABS(O7-W7),"Offer 1","Offer 3"))) | L7: =IF(OR(I7="",K7=""),"",CEILING(I7*(1+K7),5)) | M7: =IF(I7="","",IF(X7="Under",CEILING(MAX(I7*1.02,MIN(V7,W7)*0.95),5),CEILING(MAX(I7*1.03,MIN(V7,W7)*0.97),5))) | N7: =IF(I7="","",IF(X7="Under",CEILING(MAX(I7*1.03,(V7+W7)/2*0.96),5),CEILING(MAX(I7*1.05,(V7+W7)/2*0.98),5))) | O7: =IF(I7="","",IF(X7="Under",CEILING(MAX(I7*1.05,MIN(V7,W7*1.01)),5),CEILING(MAX(I7*1.08,MIN(V7,W7*1.02)),5))) | V7: =IF(C7="","",IFERROR(VLOOKUP(C7,SETUP!$A$9:$D$18,2,0),"⚠ Check SETUP")) | W7: =IF(C7="","",IFERROR(VLOOKUP(C7,SETUP!$A$9:$D$18,3,0),"⚠ Check SETUP")) | X7: =IF(C7="","",IFERROR(VLOOKUP(C7,SETUP!$A$9:$D$18,4,0),"⚠ Check SETUP")) | Y7: =IF(OR(I7="",M7=""),"",(M7-I7)/I7) | Z7: =IF(OR(I7="",N7=""),"",(N7-I7)/I7) | AA7: =IF(OR(I7="",O7=""),"",(O7-I7)/I7) | AB7: =IF(OR(Q7="",S7<>"",P7="",I7=""),"",IF(P7="Investor Override",IF(L7="","",(L7-I7)/I7),IF(P7="Offer 1",IF(M7="","",(M7-I7)/I7),IF(P7="Offer 2",IF(N7="","",(N7-I7)/I7),IF(P7="Offer 3",IF(O7="","",(O7-I7)/I7),"")))))
E8: =IF(D8="","",D8-90) | F8: =IF(D8="","",D8-60) | G8: =IF(D8="","",D8-30) | J8: =IF(I8="","",IF(ABS(N8-W8)<=ABS(M8-W8),IF(ABS(N8-W8)<=ABS(O8-W8),"Offer 2","Offer 3"),IF(ABS(M8-W8)<=ABS(O8-W8),"Offer 1","Offer 3"))) | L8: =IF(OR(I8="",K8=""),"",CEILING(I8*(1+K8),5)) | M8: =IF(I8="","",IF(X8="Under",CEILING(MAX(I8*1.02,MIN(V8,W8)*0.95),5),CEILING(MAX(I8*1.03,MIN(V8,W8)*0.97),5))) | N8: =IF(I8="","",IF(X8="Under",CEILING(MAX(I8*1.03,(V8+W8)/2*0.96),5),CEILING(MAX(I8*1.05,(V8+W8)/2*0.98),5))) | O8: =IF(I8="","",IF(X8="Under",CEILING(MAX(I8*1.05,MIN(V8,W8*1.01)),5),CEILING(MAX(I8*1.08,MIN(V8,W8*1.02)),5))) | V8: =IF(C8="","",IFERROR(VLOOKUP(C8,SETUP!$A$9:$D$18,2,0),"⚠ Check SETUP")) | W8: =IF(C8="","",IFERROR(VLOOKUP(C8,SETUP!$A$9:$D$18,3,0),"⚠ Check SETUP")) | X8: =IF(C8="","",IFERROR(VLOOKUP(C8,SETUP!$A$9:$D$18,4,0),"⚠ Check SETUP")) | Y8: =IF(OR(I8="",M8=""),"",(M8-I8)/I8) | Z8: =IF(OR(I8="",N8=""),"",(N8-I8)/I8) | AA8: =IF(OR(I8="",O8=""),"",(O8-I8)/I8) | AB8: =IF(OR(Q8="",S8<>"",P8="",I8=""),"",IF(P8="Investor Override",IF(L8="","",(L8-I8)/I8),IF(P8="Offer 1",IF(M8="","",(M8-I8)/I8),IF(P8="Offer 2",IF(N8="","",(N8-I8)/I8),IF(P8="Offer 3",IF(O8="","",(O8-I8)/I8),"")))))
E9: =IF(D9="","",D9-90) | F9: =IF(D9="","",D9-60) | G9: =IF(D9="","",D9-30) | J9: =IF(I9="","",IF(ABS(N9-W9)<=ABS(M9-W9),IF(ABS(N9-W9)<=ABS(O9-W9),"Offer 2","Offer 3"),IF(ABS(M9-W9)<=ABS(O9-W9),"Offer 1","Offer 3"))) | L9: =IF(OR(I9="",K9=""),"",CEILING(I9*(1+K9),5)) | M9: =IF(I9="","",IF(X9="Under",CEILING(MAX(I9*1.02,MIN(V9,W9)*0.95),5),CEILING(MAX(I9*1.03,MIN(V9,W9)*0.97),5))) | N9: =IF(I9="","",IF(X9="Under",CEILING(MAX(I9*1.03,(V9+W9)/2*0.96),5),CEILING(MAX(I9*1.05,(V9+W9)/2*0.98),5))) | O9: =IF(I9="","",IF(X9="Under",CEILING(MAX(I9*1.05,MIN(V9,W9*1.01)),5),CEILING(MAX(I9*1.08,MIN(V9,W9*1.02)),5))) | V9: =IF(C9="","",IFERROR(VLOOKUP(C9,SETUP!$A$9:$D$18,2,0),"⚠ Check SETUP")) | W9: =IF(C9="","",IFERROR(VLOOKUP(C9,SETUP!$A$9:$D$18,3,0),"⚠ Check SETUP")) | X9: =IF(C9="","",IFERROR(VLOOKUP(C9,SETUP!$A$9:$D$18,4,0),"⚠ Check SETUP")) | Y9: =IF(OR(I9="",M9=""),"",(M9-I9)/I9) | Z9: =IF(OR(I9="",N9=""),"",(N9-I9)/I9) | AA9: =IF(OR(I9="",O9=""),"",(O9-I9)/I9) | AB9: =IF(OR(Q9="",S9<>"",P9="",I9=""),"",IF(P9="Investor Override",IF(L9="","",(L9-I9)/I9),IF(P9="Offer 1",IF(M9="","",(M9-I9)/I9),IF(P9="Offer 2",IF(N9="","",(N9-I9)/I9),IF(P9="Offer 3",IF(O9="","",(O9-I9)/I9),"")))))
E10: =IF(D10="","",D10-90) | F10: =IF(D10="","",D10-60) | G10: =IF(D10="","",D10-30) | J10: =IF(I10="","",IF(ABS(N10-W10)<=ABS(M10-W10),IF(ABS(N10-W10)<=ABS(O10-W10),"Offer 2","Offer 3"),IF(ABS(M10-W10)<=ABS(O10-W10),"Offer 1","Offer 3"))) | L10: =IF(OR(I10="",K10=""),"",CEILING(I10*(1+K10),5)) | M10: =IF(I10="","",IF(X10="Under",CEILING(MAX(I10*1.02,MIN(V10,W10)*0.95),5),CEILING(MAX(I10*1.03,MIN(V10,W10)*0.97),5))) | N10: =IF(I10="","",IF(X10="Under",CEILING(MAX(I10*1.03,(V10+W10)/2*0.96),5),CEILING(MAX(I10*1.05,(V10+W10)/2*0.98),5))) | O10: =IF(I10="","",IF(X10="Under",CEILING(MAX(I10*1.05,MIN(V10,W10*1.01)),5),CEILING(MAX(I10*1.08,MIN(V10,W10*1.02)),5))) | V10: =IF(C10="","",IFERROR(VLOOKUP(C10,SETUP!$A$9:$D$18,2,0),"⚠ Check SETUP")) | W10: =IF(C10="","",IFERROR(VLOOKUP(C10,SETUP!$A$9:$D$18,3,0),"⚠ Check SETUP")) | X10: =IF(C10="","",IFERROR(VLOOKUP(C10,SETUP!$A$9:$D$18,4,0),"⚠ Check SETUP")) | Y10: =IF(OR(I10="",M10=""),"",(M10-I10)/I10) | Z10: =IF(OR(I10="",N10=""),"",(N10-I10)/I10) | AA10: =IF(OR(I10="",O10=""),"",(O10-I10)/I10) | AB10: =IF(OR(Q10="",S10<>"",P10="",I10=""),"",IF(P10="Investor Override",IF(L10="","",(L10-I10)/I10),IF(P10="Offer 1",IF(M10="","",(M10-I10)/I10),IF(P10="Offer 2",IF(N10="","",(N10-I10)/I10),IF(P10="Offer 3",IF(O10="","",(O10-I10)/I10),"")))))
E11: =IF(D11="","",D11-90) | F11: =IF(D11="","",D11-60) | G11: =IF(D11="","",D11-30) | J11: =IF(I11="","",IF(ABS(N11-W11)<=ABS(M11-W11),IF(ABS(N11-W11)<=ABS(O11-W11),"Offer 2","Offer 3"),IF(ABS(M11-W11)<=ABS(O11-W11),"Offer 1","Offer 3"))) | L11: =IF(OR(I11="",K11=""),"",CEILING(I11*(1+K11),5)) | M11: =IF(I11="","",IF(X11="Under",CEILING(MAX(I11*1.02,MIN(V11,W11)*0.95),5),CEILING(MAX(I11*1.03,MIN(V11,W11)*0.97),5))) | N11: =IF(I11="","",IF(X11="Under",CEILING(MAX(I11*1.03,(V11+W11)/2*0.96),5),CEILING(MAX(I11*1.05,(V11+W11)/2*0.98),5))) | O11: =IF(I11="","",IF(X11="Under",CEILING(MAX(I11*1.05,MIN(V11,W11*1.01)),5),CEILING(MAX(I11*1.08,MIN(V11,W11*1.02)),5))) | V11: =IF(C11="","",IFERROR(VLOOKUP(C11,SETUP!$A$9:$D$18,2,0),"⚠ Check SETUP")) | W11: =IF(C11="","",IFERROR(VLOOKUP(C11,SETUP!$A$9:$D$18,3,0),"⚠ Check SETUP")) | X11: =IF(C11="","",IFERROR(VLOOKUP(C11,SETUP!$A$9:$D$18,4,0),"⚠ Check SETUP")) | Y11: =IF(OR(I11="",M11=""),"",(M11-I11)/I11) | Z11: =IF(OR(I11="",N11=""),"",(N11-I11)/I11) | AA11: =IF(OR(I11="",O11=""),"",(O11-I11)/I11) | AB11: =IF(OR(Q11="",S11<>"",P11="",I11=""),"",IF(P11="Investor Override",IF(L11="","",(L11-I11)/I11),IF(P11="Offer 1",IF(M11="","",(M11-I11)/I11),IF(P11="Offer 2",IF(N11="","",(N11-I11)/I11),IF(P11="Offer 3",IF(O11="","",(O11-I11)/I11),"")))))
E12: =IF(D12="","",D12-90) | F12: =IF(D12="","",D12-60) | G12: =IF(D12="","",D12-30) | J12: =IF(I12="","",IF(ABS(N12-W12)<=ABS(M12-W12),IF(ABS(N12-W12)<=ABS(O12-W12),"Offer 2","Offer 3"),IF(ABS(M12-W12)<=ABS(O12-W12),"Offer 1","Offer 3"))) | L12: =IF(OR(I12="",K12=""),"",CEILING(I12*(1+K12),5)) | M12: =IF(I12="","",IF(X12="Under",CEILING(MAX(I12*1.02,MIN(V12,W12)*0.95),5),CEILING(MAX(I12*1.03,MIN(V12,W12)*0.97),5))) | N12: =IF(I12="","",IF(X12="Under",CEILING(MAX(I12*1.03,(V12+W12)/2*0.96),5),CEILING(MAX(I12*1.05,(V12+W12)/2*0.98),5))) | O12: =IF(I12="","",IF(X12="Under",CEILING(MAX(I12*1.05,MIN(V12,W12*1.01)),5),CEILING(MAX(I12*1.08,MIN(V12,W12*1.02)),5))) | V12: =IF(C12="","",IFERROR(VLOOKUP(C12,SETUP!$A$9:$D$18,2,0),"⚠ Check SETUP")) | W12: =IF(C12="","",IFERROR(VLOOKUP(C12,SETUP!$A$9:$D$18,3,0),"⚠ Check SETUP")) | X12: =IF(C12="","",IFERROR(VLOOKUP(C12,SETUP!$A$9:$D$18,4,0),"⚠ Check SETUP")) | Y12: =IF(OR(I12="",M12=""),"",(M12-I12)/I12) | Z12: =IF(OR(I12="",N12=""),"",(N12-I12)/I12) | AA12: =IF(OR(I12="",O12=""),"",(O12-I12)/I12) | AB12: =IF(OR(Q12="",S12<>"",P12="",I12=""),"",IF(P12="Investor Override",IF(L12="","",(L12-I12)/I12),IF(P12="Offer 1",IF(M12="","",(M12-I12)/I12),IF(P12="Offer 2",IF(N12="","",(N12-I12)/I12),IF(P12="Offer 3",IF(O12="","",(O12-I12)/I12),"")))))
E13: =IF(D13="","",D13-90) | F13: =IF(D13="","",D13-60) | G13: =IF(D13="","",D13-30) | J13: =IF(I13="","",IF(ABS(N13-W13)<=ABS(M13-W13),IF(ABS(N13-W13)<=ABS(O13-W13),"Offer 2","Offer 3"),IF(ABS(M13-W13)<=ABS(O13-W13),"Offer 1","Offer 3"))) | L13: =IF(OR(I13="",K13=""),"",CEILING(I13*(1+K13),5)) | M13: =IF(I13="","",IF(X13="Under",CEILING(MAX(I13*1.02,MIN(V13,W13)*0.95),5),CEILING(MAX(I13*1.03,MIN(V13,W13)*0.97),5))) | N13: =IF(I13="","",IF(X13="Under",CEILING(MAX(I13*1.03,(V13+W13)/2*0.96),5),CEILING(MAX(I13*1.05,(V13+W13)/2*0.98),5))) | O13: =IF(I13="","",IF(X13="Under",CEILING(MAX(I13*1.05,MIN(V13,W13*1.01)),5),CEILING(MAX(I13*1.08,MIN(V13,W13*1.02)),5))) | V13: =IF(C13="","",IFERROR(VLOOKUP(C13,SETUP!$A$9:$D$18,2,0),"⚠ Check SETUP")) | W13: =IF(C13="","",IFERROR(VLOOKUP(C13,SETUP!$A$9:$D$18,3,0),"⚠ Check SETUP")) | X13: =IF(C13="","",IFERROR(VLOOKUP(C13,SETUP!$A$9:$D$18,4,0),"⚠ Check SETUP")) | Y13: =IF(OR(I13="",M13=""),"",(M13-I13)/I13) | Z13: =IF(OR(I13="",N13=""),"",(N13-I13)/I13) | AA13: =IF(OR(I13="",O13=""),"",(O13-I13)/I13) | AB13: =IF(OR(Q13="",S13<>"",P13="",I13=""),"",IF(P13="Investor Override",IF(L13="","",(L13-I13)/I13),IF(P13="Offer 1",IF(M13="","",(M13-I13)/I13),IF(P13="Offer 2",IF(N13="","",(N13-I13)/I13),IF(P13="Offer 3",IF(O13="","",(O13-I13)/I13),"")))))
E14: =IF(D14="","",D14-90) | F14: =IF(D14="","",D14-60) | G14: =IF(D14="","",D14-30) | J14: =IF(I14="","",IF(ABS(N14-W14)<=ABS(M14-W14),IF(ABS(N14-W14)<=ABS(O14-W14),"Offer 2","Offer 3"),IF(ABS(M14-W14)<=ABS(O14-W14),"Offer 1","Offer 3"))) | L14: =IF(OR(I14="",K14=""),"",CEILING(I14*(1+K14),5)) | M14: =IF(I14="","",IF(X14="Under",CEILING(MAX(I14*1.02,MIN(V14,W14)*0.95),5),CEILING(MAX(I14*1.03,MIN(V14,W14)*0.97),5))) | N14: =IF(I14="","",IF(X14="Under",CEILING(MAX(I14*1.03,(V14+W14)/2*0.96),5),CEILING(MAX(I14*1.05,(V14+W14)/2*0.98),5))) | O14: =IF(I14="","",IF(X14="Under",CEILING(MAX(I14*1.05,MIN(V14,W14*1.01)),5),CEILING(MAX(I14*1.08,MIN(V14,W14*1.02)),5))) | V14: =IF(C14="","",IFERROR(VLOOKUP(C14,SETUP!$A$9:$D$18,2,0),"⚠ Check SETUP")) | W14: =IF(C14="","",IFERROR(VLOOKUP(C14,SETUP!$A$9:$D$18,3,0),"⚠ Check SETUP")) | X14: =IF(C14="","",IFERROR(VLOOKUP(C14,SETUP!$A$9:$D$18,4,0),"⚠ Check SETUP")) | Y14: =IF(OR(I14="",M14=""),"",(M14-I14)/I14) | Z14: =IF(OR(I14="",N14=""),"",(N14-I14)/I14) | AA14: =IF(OR(I14="",O14=""),"",(O14-I14)/I14) | AB14: =IF(OR(Q14="",S14<>"",P14="",I14=""),"",IF(P14="Investor Override",IF(L14="","",(L14-I14)/I14),IF(P14="Offer 1",IF(M14="","",(M14-I14)/I14),IF(P14="Offer 2",IF(N14="","",(N14-I14)/I14),IF(P14="Offer 3",IF(O14="","",(O14-I14)/I14),"")))))
E15: =IF(D15="","",D15-90) | F15: =IF(D15="","",D15-60) | G15: =IF(D15="","",D15-30) | J15: =IF(I15="","",IF(ABS(N15-W15)<=ABS(M15-W15),IF(ABS(N15-W15)<=ABS(O15-W15),"Offer 2","Offer 3"),IF(ABS(M15-W15)<=ABS(O15-W15),"Offer 1","Offer 3"))) | L15: =IF(OR(I15="",K15=""),"",CEILING(I15*(1+K15),5)) | M15: =IF(I15="","",IF(X15="Under",CEILING(MAX(I15*1.02,MIN(V15,W15)*0.95),5),CEILING(MAX(I15*1.03,MIN(V15,W15)*0.97),5))) | N15: =IF(I15="","",IF(X15="Under",CEILING(MAX(I15*1.03,(V15+W15)/2*0.96),5),CEILING(MAX(I15*1.05,(V15+W15)/2*0.98),5))) | O15: =IF(I15="","",IF(X15="Under",CEILING(MAX(I15*1.05,MIN(V15,W15*1.01)),5),CEILING(MAX(I15*1.08,MIN(V15,W15*1.02)),5))) | V15: =IF(C15="","",IFERROR(VLOOKUP(C15,SETUP!$A$9:$D$18,2,0),"⚠ Check SETUP")) | W15: =IF(C15="","",IFERROR(VLOOKUP(C15,SETUP!$A$9:$D$18,3,0),"⚠ Check SETUP")) | X15: =IF(C15="","",IFERROR(VLOOKUP(C15,SETUP!$A$9:$D$18,4,0),"⚠ Check SETUP")) | Y15: =IF(OR(I15="",M15=""),"",(M15-I15)/I15) | Z15: =IF(OR(I15="",N15=""),"",(N15-I15)/I15) | AA15: =IF(OR(I15="",O15=""),"",(O15-I15)/I15) | AB15: =IF(OR(Q15="",S15<>"",P15="",I15=""),"",IF(P15="Investor Override",IF(L15="","",(L15-I15)/I15),IF(P15="Offer 1",IF(M15="","",(M15-I15)/I15),IF(P15="Offer 2",IF(N15="","",(N15-I15)/I15),IF(P15="Offer 3",IF(O15="","",(O15-I15)/I15),"")))))
... E33: =IF(D33="","",D33-90) | F33: =IF(D33="","",D33-60) | G33: =IF(D33="","",D33-30) | J33: =IF(I33="","",IF(ABS(N33-W33)<=ABS(M33-W33),IF(ABS(N33-W33)<=ABS(O33-W33),"Offer 2","Offer 3"),IF(ABS(M33-W33)<=ABS(O33-W33),"Offer 1","Offer 3"))) | L33: =IF(OR(I33="",K33=""),"",CEILING(I33*(1+K33),5)) | M33: =IF(I33="","",IF(X33="Under",CEILING(MAX(I33*1.02,MIN(V33,W33)*0.95),5),CEILING(MAX(I33*1.03,MIN(V33,W33)*0.97),5))) | N33: =IF(I33="","",IF(X33="Under",CEILING(MAX(I33*1.03,(V33+W33)/2*0.96),5),CEILING(MAX(I33*1.05,(V33+W33)/2*0.98),5))) | O33: =IF(I33="","",IF(X33="Under",CEILING(MAX(I33*1.05,MIN(V33,W33*1.01)),5),CEILING(MAX(I33*1.08,MIN(V33,W33*1.02)),5))) | V33: =IF(C33="","",IFERROR(VLOOKUP(C33,SETUP!$A$9:$D$18,2,0),"⚠ Check SETUP")) | W33: =IF(C33="","",IFERROR(VLOOKUP(C33,SETUP!$A$9:$D$18,3,0),"⚠ Check SETUP")) | X33: =IF(C33="","",IFERROR(VLOOKUP(C33,SETUP!$A$9:$D$18,4,0),"⚠ Check SETUP")) | Y33: =IF(OR(I33="",M33=""),"",(M33-I33)/I33) | Z33: =IF(OR(I33="",N33=""),"",(N33-I33)/I33) | AA33: =IF(OR(I33="",O33=""),"",(O33-I33)/I33) | AB33: =IF(OR(Q33="",S33<>"",P33="",I33=""),"",IF(P33="Investor Override",IF(L33="","",(L33-I33)/I33),IF(P33="Offer 1",IF(M33="","",(M33-I33)/I33),IF(P33="Offer 2",IF(N33="","",(N33-I33)/I33),IF(P33="Offer 3",IF(O33="","",(O33-I33)/I33),"")))))
X34: Portfolio Avg (Excl. NTV) → | Y34: =IFERROR(AVERAGEIFS(Y4:Y33,S4:S33,""),"") | Z34: =IFERROR(AVERAGEIFS(Z4:Z33,S4:S33,""),"") | AA34: =IFERROR(AVERAGEIFS(AA4:AA33,S4:S33,""),"") | AB34: =IFERROR(AVERAGEIF(AB4:AB33,"<>"),"")
A36: RETENTION ANALYSIS
A37: Metric | B37: Count | C37: % of Expirations | D37: % of Decided | E37: Status
A38: Total Lease Expirations | B38: =COUNTA(A4:A33)
A39: Renewals Signed | B39: =COUNTA(Q4:Q33) | C39: =IFERROR(B39/B38,"-") | D39: =IFERROR(B39/(B39+B40),"-") | E39: =IF(B38=0,"Awaiting data",IF(B39/B38>=0.6,"On Track ✓","Needs Attention ⚠"))
A40: NTV's Received | B40: =COUNTA(S4:S33) | C40: =IFERROR(B40/B38,"-") | D40: =IFERROR(B40/(B39+B40),"-") | E40: =IF(B38=0,"Awaiting data",IF(B40/B38<=0.2,"Acceptable","High NTV ⚠"))
A41: Transfers | B41: =COUNTA(R4:R33) | C41: =IFERROR(B41/B38,"-") | D41: — | E41: Resident retained in portfolio
A42: Pending / Not Yet Decided | B42: =MAX(0,B38-B39-B40-B41) | C42: =IFERROR(B42/B38,"-") | D42: — | E42: =IF(B42=0,"All accounted for ✓","Follow up needed")
A44: RETENTION RATE (Renewals ÷ Total Expirations) | C44: =IFERROR(B39/B38,"-") | D44: =IF(B38=0,"Enter resident data to calculate",IF(B39/B38>=0.6,"✓ Meeting target retention","⚠ Below target — review offers"))
A45: RETENTION RATE (Renewals ÷ Renewals + NTVs) ← of decided residents | C45: =IFERROR(B39/(B39+B40),"-") | D45: Excludes pending residents — only counts those who have made a decision (renewed or NTV'd)
A48: Legend
A49: Renewed (auto: enter date in Renewal Signed)
A50: Pending Signature (manual: apply yellow fill)
A51: NTV / Notice to Vacate (auto: enter date in NTV Rcv'd)
A52: Transfer (auto: enter date in Transfer)
A53: MTM / Month-to-Month (manual: apply gray fill)
